Train Epoch: 9 [14656/15040 (97%)] Loss: 0.066730
Train Epoch: 10 [14656/15040 (97%)] Loss: 0.037900
Train Epoch: 11 [14656/15040 (97%)] Loss: 0.003191
Train Epoch: 12 [14656/15040 (97%)] Loss: 0.061655
DEBUG flower 2020-11-01 01:40:47,755 | connection.py:35 | ChannelConnectivity.IDLE
DEBUG flower 2020-11-01 01:40:48,749 | connection.py:67 | Insecure gRPC channel closed
Traceback (most recent call last):
  File "/usr/local/lib/python3.7/runpy.py", line 193, in _run_module_as_main
    "__main__", mod_spec)
  File "/usr/local/lib/python3.7/runpy.py", line 85, in _run_code
    exec(code, run_globals)
  File "/app/src/py/flwr_example/mnist_app/client.py", line 103, in <module>
    fl.client.start_client(args.server_address, client)
  File "/app/src/py/flwr/client/app.py", line 35, in start_client
    server_message = receive()
  File "/app/src/py/flwr/client/grpc_client/connection.py", line 59, in <lambda>
    receive: Callable[[], ServerMessage] = lambda: next(server_message_iterator)
  File "/usr/local/lib/python3.7/site-packages/grpc/_channel.py", line 416, in __next__
    return self._next()
  File "/usr/local/lib/python3.7/site-packages/grpc/_channel.py", line 803, in _next
    raise self
grpc._channel._MultiThreadedRendezvous: <_MultiThreadedRendezvous of RPC that terminated with:
        status = StatusCode.UNAVAILABLE
        details = "Socket closed"
        debug_error_string = "{"created":"@1604194848.697064900","description":"Error received from peer ipv4:172.21.0.3:8080","file":"src/core/lib/surface/call.cc","file_line":1061,"grpc_message":"Socket closed","grpc_status":14}"
>
Client 1 - Evaluate on 2500 samples: Average loss: 0.0441, Accuracy: 98.60%

Client 1 - Evaluate on 2500 samples: Average loss: 0.0441, Accuracy: 98.60%